<?xml version="1.0" ?>
<!-- =================================================================================== -->
<!-- |    This document was autogenerated by xacro from rg2_gripper.xacro              | -->
<!-- |    EDITING THIS FILE BY HAND IS NOT RECOMMENDED                                 | -->
<!-- =================================================================================== -->
<robot name="rg2_gripper">
  <material name="silver_default">
    <color rgba="0.700 0.700 0.700 1.000"/>
  </material>
  <material name="blue_default">
    <color rgba="0.700 0.700 0.800 1.000"/>
  </material>
  <material name="dark_default">
    <color rgba="0.400 0.400 0.400 1.000"/>
  </material>
  <material name="green_default">
    <color rgba="0.700 0.800 0.700 1.000"/>
  </material>


  <link name="base_link">
    <inertial>
      <origin rpy="0 0 0" xyz="-0.00033928396113482284 0.0001550803374992693 0.06397335096404132"/>
      <mass value="0.7151802197889529"/>
      <inertia ixx="0.001268" ixy="0.0" ixz="-1.2e-05" iyy="0.001154" iyz="3e-06" izz="0.000357"/>
    </inertial>
    <visual>
      <origin rpy="0 0 0" xyz="0 0 0"/>
      <geometry>
        <mesh filename="meshes/rg2_gripper/base_link.obj" scale="0.001 0.001 0.001"/>
      </geometry>
      <material name="silver_default"/>
    </visual>
    <collision>
      <origin rpy="0 0 0" xyz="0 0 0"/>
      <geometry>
        <mesh filename="meshes/rg2_gripper/base_link.obj" scale="0.001 0.001 0.001"/>
      </geometry>
    </collision>
  </link>
  <link name="left_outer_link_1">
    <inertial>
      <origin rpy="0 0 0" xyz="0.009999996523330909 0.0017814726549052681 0.012228209292930586"/>
      <mass value="0.03836739327168093"/>
      <inertia ixx="1.4e-05" ixy="0.0" ixz="0.0" iyy="1.4e-05" iyz="-0.0" izz="3e-06"/>
    </inertial>
    <visual>
      <origin rpy="0 0 0" xyz="0.0103 -0.01705 -0.12275"/>
      <geometry>
        <mesh filename="meshes/rg2_gripper/left_outer_link_1.obj" scale="0.001 0.001 0.001"/>
      </geometry>
      <material name="blue_default"/>
    </visual>
    <collision>
      <origin rpy="0 0 0" xyz="0.0103 -0.01705 -0.12275"/>
      <geometry>
        <mesh filename="meshes/rg2_gripper/left_outer_link_1.obj" scale="0.001 0.001 0.001"/>
      </geometry>
    </collision>
  </link>
  <link name="left_finger_link_1">
    <inertial>
      <origin rpy="0 0 0" xyz="0.010012780774690653 -0.010687647568749598 0.027402616106703998"/>
      <mass value="0.02483517715757534"/>
      <inertia ixx="7e-06" ixy="-0.0" ixz="0.0" iyy="6e-06" iyz="2e-06" izz="1e-06"/>
    </inertial>
    <visual>
      <origin rpy="0 0 0" xyz="0.0103 -0.01902 -0.177715"/>
      <geometry>
        <mesh filename="meshes/rg2_gripper/left_finger_link_1.obj" scale="0.001 0.001 0.001"/>
      </geometry>
      <material name="dark_default"/>
    </visual>
    <collision>
      <origin rpy="0 0 0" xyz="0.0103 -0.01902 -0.177715"/>
      <geometry>
        <mesh filename="meshes/rg2_gripper/left_finger_link_1.obj" scale="0.001 0.001 0.001"/>
      </geometry>
    </collision>
  </link>
  <link name="left_inner_link_1">
    <inertial>
      <origin rpy="0 0 0" xyz="0.010005296596915006 -0.0016937268392717038 -0.03516232888579532"/>
      <mass value="0.012641568013611078"/>
      <inertia ixx="5e-06" ixy="0.0" ixz="-0.0" iyy="6e-06" iyz="-0.0" izz="1e-06"/>
    </inertial>
    <visual>
      <origin rpy="0 0 0" xyz="0.0103 -0.00952 -0.194215"/>
      <geometry>
        <mesh filename="meshes/rg2_gripper/left_inner_link_1.obj" scale="0.001 0.001 0.001"/>
      </geometry>
      <material name="green_default"/>
    </visual>
    <collision>
      <origin rpy="0 0 0" xyz="0.0103 -0.00952 -0.194215"/>
      <geometry>
        <mesh filename="meshes/rg2_gripper/left_inner_link_1.obj" scale="0.001 0.001 0.001"/>
      </geometry>
    </collision>
  </link>
  <link name="right_outer_link_1">
    <inertial>
      <origin rpy="0 0 0" xyz="0.010000003486636795 -0.0017814726548893677 0.012228209293019432"/>
      <mass value="0.03836739327185006"/>
      <inertia ixx="1.4e-05" ixy="0.0" ixz="-0.0" iyy="1.4e-05" iyz="0.0" izz="3e-06"/>
    </inertial>
    <visual>
      <origin rpy="0 0 0" xyz="0.0103 0.01695 -0.12275"/>
      <geometry>
        <mesh filename="meshes/rg2_gripper/right_outer_link_1.obj" scale="0.001 0.001 0.001"/>
      </geometry>
      <material name="blue_default"/>
    </visual>
    <collision>
      <origin rpy="0 0 0" xyz="0.0103 0.01695 -0.12275"/>
      <geometry>
        <mesh filename="meshes/rg2_gripper/right_outer_link_1.obj" scale="0.001 0.001 0.001"/>
      </geometry>
    </collision>
  </link>
  <link name="right_finger_link_1">
    <inertial>
      <origin rpy="0 0 0" xyz="0.009987219235276384 0.010687647568778226 0.02740261610670347"/>
      <mass value="0.02483517715757534"/>
      <inertia ixx="7e-06" ixy="-0.0" ixz="-0.0" iyy="6e-06" iyz="-2e-06" izz="1e-06"/>
    </inertial>
    <visual>
      <origin rpy="0 0 0" xyz="0.0103 0.01892 -0.177715"/>
      <geometry>
        <mesh filename="meshes/rg2_gripper/right_finger_link_1.obj" scale="0.001 0.001 0.001"/>
      </geometry>
      <material name="dark_default"/>
    </visual>
    <collision>
      <origin rpy="0 0 0" xyz="0.0103 0.01892 -0.177715"/>
      <geometry>
        <mesh filename="meshes/rg2_gripper/right_finger_link_1.obj" scale="0.001 0.001 0.001"/>
      </geometry>
    </collision>
  </link>
  <link name="right_inner_link_1">
    <inertial>
      <origin rpy="0 0 0" xyz="0.00999470341305246 0.001693726839305438 -0.035162328885795485"/>
      <mass value="0.012641568013611078"/>
      <inertia ixx="5e-06" ixy="0.0" ixz="0.0" iyy="6e-06" iyz="0.0" izz="1e-06"/>
    </inertial>
    <visual>
      <origin rpy="0 0 0" xyz="0.0103 0.00942 -0.194215"/>
      <geometry>
        <mesh filename="meshes/rg2_gripper/right_inner_link_1.obj" scale="0.001 0.001 0.001"/>
      </geometry>
      <material name="green_default"/>
    </visual>
    <collision>
      <origin rpy="0 0 0" xyz="0.0103 0.00942 -0.194215"/>
      <geometry>
        <mesh filename="meshes/rg2_gripper/right_inner_link_1.obj" scale="0.001 0.001 0.001"/>
      </geometry>
    </collision>
  </link>
  <joint name="Rev33" type="revolute">
    <origin rpy="0 0 0" xyz="-0.0103 0.01705 0.12275"/>
    <parent link="base_link"/>
    <child link="left_outer_link_1"/>
    <axis xyz="-1.0 0.0 0.0"/>
    <limit effort="100" lower="0.0" upper="1.343904" velocity="100"/>
  </joint>
  <joint name="Rev29" type="revolute">
    <origin rpy="0 0 0" xyz="0.0 0.00197 0.054965"/>
    <parent link="left_outer_link_1"/>
    <child link="left_finger_link_1"/>
    <axis xyz="1.0 -0.0 -0.0"/>
    <limit effort="200" lower="0.0" upper="1.343904" velocity="100"/>
  </joint>
  <joint name="Rev30" type="revolute">
    <origin rpy="0 0 0" xyz="0.0 -0.0095 0.0165"/>
    <parent link="left_finger_link_1"/>
    <child link="left_inner_link_1"/>
    <axis xyz="-1.0 -0.0 -0.0"/>
    <limit effort="200" lower="0.0" upper="1.343904" velocity="100"/>
  </joint>
  <joint name="Rev28" type="revolute">
    <origin rpy="0 0 0" xyz="-0.0103 -0.01695 0.12275"/>
    <parent link="base_link"/>
    <child link="right_outer_link_1"/>
    <axis xyz="1.0 0.0 0.0"/>
    <limit effort="100" lower="0.0" upper="1.343904" velocity="100"/>
  </joint>
  <joint name="Rev34" type="revolute">
    <origin rpy="0 0 0" xyz="0.0 -0.00197 0.054965"/>
    <parent link="right_outer_link_1"/>
    <child link="right_finger_link_1"/>
    <axis xyz="-1.0 -0.0 -0.0"/>
    <limit effort="200" lower="0.0" upper="1.343904" velocity="100"/>
  </joint>
  <joint name="Rev35" type="revolute">
    <origin rpy="0 0 0" xyz="0.0 0.0095 0.0165"/>
    <parent link="right_finger_link_1"/>
    <child link="right_inner_link_1"/>
    <axis xyz="1.0 0.0 -0.0"/>
    <limit effort="200" lower="0.0" upper="1.343904" velocity="100"/>
  </joint>
</robot>
