<?xml version="1.0" ?>
<!-- =================================================================================== -->
<!-- |    This document was autogenerated by xacro from ur.urdf.xacro                  | -->
<!-- |    EDITING THIS FILE BY HAND IS NOT RECOMMENDED                                 | -->
<!-- =================================================================================== -->
<robot name="ur5_rg2">
  <link name="base_link">
    <inertial>
      <mass value="0.0"/>
      <origin rpy="0 0 0" xyz="0 0 0"/>
      <inertia ixx="0.0" ixy="0.0" ixz="0.0" iyy="0.0" iyz="0.0" izz="0.0"/>
    </inertial>
  </link>
  <link name="base_link_inertia">
    <visual>
      <origin rpy="0 0 3.141592653589793" xyz="0 0 0"/>
      <geometry>
        <mesh filename="meshes/ur5/visual/base.obj"/>
      </geometry>
      <material name="LightGrey">
        <color rgba="0.7 0.7 0.7 1.0"/>
      </material>
    </visual>
    <collision>
      <origin rpy="0 0 3.141592653589793" xyz="0 0 0"/>
      <geometry>
        <mesh filename="meshes/ur5/collision/base.obj"/>
      </geometry>
    </collision>
    <inertial>
      <mass value="4.0"/>
      <origin rpy="0 0 0" xyz="0 0 0"/>
      <inertia ixx="0.00443333156" ixy="0.0" ixz="0.0" iyy="0.00443333156" iyz="0.0" izz="0.0072"/>
    </inertial>
  </link>
  <link name="shoulder_link">
    <visual>
      <origin rpy="0 0 3.141592653589793" xyz="0 0 0"/>
      <geometry>
        <mesh filename="meshes/ur5/visual/shoulder.obj"/>
      </geometry>
      <material name="LightBlue">
        <color rgba="0.7 0.7 0.8 1.0"/>
      </material>
    </visual>
    <collision>
      <origin rpy="0 0 3.141592653589793" xyz="0 0 0"/>
      <geometry>
        <mesh filename="meshes/ur5/collision/shoulder.obj"/>
      </geometry>
    </collision>
    <inertial>
      <mass value="3.7"/>
      <origin rpy="0 0 0" xyz="0 0 0"/>
      <inertia ixx="0.014972352344389999" ixy="0.0" ixz="0.0" iyy="0.014972352344389999" iyz="0.0" izz="0.01040625"/>
    </inertial>
  </link>
  <link name="upper_arm_link">
    <visual>
      <origin rpy="1.5707963267948966 0 -1.5707963267948966" xyz="0 0 0.13585"/>
      <geometry>
        <mesh filename="meshes/ur5/visual/upperarm.obj"/>
      </geometry>
      <material name="LightGreen">
        <color rgba="0.7 0.8 0.7 1.0"/>
      </material>
    </visual>
    <collision>
      <origin rpy="1.5707963267948966 0 -1.5707963267948966" xyz="0 0 0.13585"/>
      <geometry>
        <mesh filename="meshes/ur5/collision/upperarm.obj"/>
      </geometry>
    </collision>
    <inertial>
      <mass value="8.393"/>
      <origin rpy="0 1.5707963267948966 0" xyz="-0.2125 0.0 0.136"/>
      <inertia ixx="0.1338857818623325" ixy="0.0" ixz="0.0" iyy="0.1338857818623325" iyz="0.0" izz="0.0151074"/>
    </inertial>
  </link>
  <link name="forearm_link">
    <visual>
      <origin rpy="1.5707963267948966 0 -1.5707963267948966" xyz="0 0 0.0165"/>
      <geometry>
        <mesh filename="meshes/ur5/visual/forearm.obj"/>
      </geometry>
      <material name="LightRed">
        <color rgba="0.8 0.7 0.7 1.0"/>
      </material>
    </visual>
    <collision>
      <origin rpy="1.5707963267948966 0 -1.5707963267948966" xyz="0 0 0.0165"/>
      <geometry>
        <mesh filename="meshes/ur5/collision/forearm.obj"/>
      </geometry>
    </collision>
    <inertial>
      <mass value="2.275"/>
      <origin rpy="0 1.5707963267948966 0" xyz="-0.196125 0.0 0.0165"/>
      <inertia ixx="0.03121679102890359" ixy="0.0" ixz="0.0" iyy="0.03121679102890359" iyz="0.0" izz="0.004095"/>
    </inertial>
  </link>
  <link name="wrist_1_link">
    <visual>
      <origin rpy="1.5707963267948966 0 0" xyz="0 0 -0.093"/>
      <geometry>
        <mesh filename="meshes/ur5/visual/wrist1.obj"/>
      </geometry>
      <material name="LightGrey">
        <color rgba="0.7 0.7 0.7 1.0"/>
      </material>
    </visual>
    <collision>
      <origin rpy="1.5707963267948966 0 0" xyz="0 0 -0.093"/>
      <geometry>
        <mesh filename="meshes/ur5/collision/wrist1.obj"/>
      </geometry>
    </collision>
    <inertial>
      <mass value="1.219"/>
      <origin rpy="0 0 0" xyz="0 0 0"/>
      <inertia ixx="0.0020138887777775" ixy="0.0" ixz="0.0" iyy="0.0020138887777775" iyz="0.0" izz="0.0021942"/>
    </inertial>
  </link>
  <link name="wrist_2_link">
    <visual>
      <origin rpy="0 0 0" xyz="0 0 -0.095"/>
      <geometry>
        <mesh filename="meshes/ur5/visual/wrist2.obj"/>
      </geometry>
      <material name="LightBlue">
        <color rgba="0.7 0.7 0.8 1.0"/>
      </material>
    </visual>
    <collision>
      <origin rpy="0 0 0" xyz="0 0 -0.095"/>
      <geometry>
        <mesh filename="meshes/ur5/collision/wrist2.obj"/>
      </geometry>
    </collision>
    <inertial>
      <mass value="1.219"/>
      <origin rpy="0 0 0" xyz="0 0 0"/>
      <inertia ixx="0.0018310388509175" ixy="0.0" ixz="0.0" iyy="0.0018310388509175" iyz="0.0" izz="0.0021942"/>
    </inertial>
  </link>
  <link name="wrist_3_link">
    <visual>
      <origin rpy="1.5707963267948966 0 0" xyz="0 0 -0.0818"/>
      <geometry>
        <mesh filename="meshes/ur5/visual/wrist3.obj"/>
      </geometry>
      <material name="LightGreen">
        <color rgba="0.7 0.8 0.7 1.0"/>
      </material>
    </visual>
    <collision>
      <origin rpy="1.5707963267948966 0 0" xyz="0 0 -0.0818"/>
      <geometry>
        <mesh filename="meshes/ur5/collision/wrist3.obj"/>
      </geometry>
    </collision>
    <inertial>
      <mass value="0.1879"/>
      <origin rpy="0 0 0" xyz="0.0 0.0 -0.01525"/>
      <inertia ixx="8.062472608343e-05" ixy="0.0" ixz="0.0" iyy="8.062472608343e-05" iyz="0.0" izz="0.0001321171875"/>
    </inertial>
  </link>
  <!-- Gripper Links -->
  <material name="silver_default">
    <color rgba="0.700 0.700 0.700 1.000"/>
  </material>
  <material name="blue_default">
    <color rgba="0.700 0.700 0.800 1.000"/>
  </material>
  <material name="dark_default">
    <color rgba="0.400 0.400 0.400 1.000"/>
  </material>
  <material name="green_default">
    <color rgba="0.700 0.800 0.700 1.000"/>
  </material>
  <link name="base_link_rg2">
    <inertial>
      <origin rpy="0 0 0" xyz="-0.00033928396113482284 0.0001550803374992693 0.06397335096404132"/>
      <mass value="0.7151802197889529"/>
      <inertia ixx="0.001268" ixy="0.0" ixz="-1.2e-05" iyy="0.001154" iyz="3e-06" izz="0.000357"/>
    </inertial>
    <visual>
      <origin rpy="0 0 0" xyz="0 0 0"/>
      <geometry>
        <mesh filename="meshes/rg2_gripper/base_link.obj" scale="0.001 0.001 0.001"/>
      </geometry>
      <material name="silver_default"/>
    </visual>
    <collision>
      <origin rpy="0 0 0" xyz="0 0 0"/>
      <geometry>
        <mesh filename="meshes/rg2_gripper/base_link.obj" scale="0.001 0.001 0.001"/>
      </geometry>
    </collision>
  </link>
  <link name="left_outer_link_1">
    <inertial>
      <origin rpy="0 0 0" xyz="0.009999996523330909 0.0017814726549052681 0.012228209292930586"/>
      <mass value="0.03836739327168093"/>
      <inertia ixx="1.4e-05" ixy="0.0" ixz="0.0" iyy="1.4e-05" iyz="-0.0" izz="3e-06"/>
    </inertial>
    <visual>
      <origin rpy="0 0 0" xyz="0.0103 -0.01705 -0.12275"/>
      <geometry>
        <mesh filename="meshes/rg2_gripper/left_outer_link_1.obj" scale="0.001 0.001 0.001"/>
      </geometry>
      <material name="blue_default"/>
    </visual>
    <collision>
      <origin rpy="0 0 0" xyz="0.0103 -0.01705 -0.12275"/>
      <geometry>
        <mesh filename="meshes/rg2_gripper/left_outer_link_1.obj" scale="0.001 0.001 0.001"/>
      </geometry>
    </collision>
  </link>
  <link name="left_finger_link_1">
    <inertial>
      <origin rpy="0 0 0" xyz="0.010012780774690653 -0.010687647568749598 0.027402616106703998"/>
      <mass value="0.02483517715757534"/>
      <inertia ixx="7e-06" ixy="-0.0" ixz="0.0" iyy="6e-06" iyz="2e-06" izz="1e-06"/>
    </inertial>
    <visual>
      <origin rpy="0 0 0" xyz="0.0103 -0.01902 -0.177715"/>
      <geometry>
        <mesh filename="meshes/rg2_gripper/left_finger_link_1.obj" scale="0.001 0.001 0.001"/>
      </geometry>
      <material name="dark_default"/>
    </visual>
    <collision>
      <origin rpy="0 0 0" xyz="0.0103 -0.01902 -0.177715"/>
      <geometry>
        <mesh filename="meshes/rg2_gripper/left_finger_link_1.obj" scale="0.001 0.001 0.001"/>
      </geometry>
    </collision>
  </link>
  <link name="left_inner_link_1">
    <inertial>
      <origin rpy="0 0 0" xyz="0.010005296596915006 -0.0016937268392717038 -0.03516232888579532"/>
      <mass value="0.012641568013611078"/>
      <inertia ixx="5e-06" ixy="0.0" ixz="-0.0" iyy="6e-06" iyz="-0.0" izz="1e-06"/>
    </inertial>
    <visual>
      <origin rpy="0 0 0" xyz="0.0103 -0.00952 -0.194215"/>
      <geometry>
        <mesh filename="meshes/rg2_gripper/left_inner_link_1.obj" scale="0.001 0.001 0.001"/>
      </geometry>
      <material name="green_default"/>
    </visual>
    <collision>
      <origin rpy="0 0 0" xyz="0.0103 -0.00952 -0.194215"/>
      <geometry>
        <mesh filename="meshes/rg2_gripper/left_inner_link_1.obj" scale="0.001 0.001 0.001"/>
      </geometry>
    </collision>
  </link>
  <link name="right_outer_link_1">
    <inertial>
      <origin rpy="0 0 0" xyz="0.010000003486636795 -0.0017814726548893677 0.012228209293019432"/>
      <mass value="0.03836739327185006"/>
      <inertia ixx="1.4e-05" ixy="0.0" ixz="-0.0" iyy="1.4e-05" iyz="0.0" izz="3e-06"/>
    </inertial>
    <visual>
      <origin rpy="0 0 0" xyz="0.0103 0.01695 -0.12275"/>
      <geometry>
        <mesh filename="meshes/rg2_gripper/right_outer_link_1.obj" scale="0.001 0.001 0.001"/>
      </geometry>
      <material name="blue_default"/>
    </visual>
    <collision>
      <origin rpy="0 0 0" xyz="0.0103 0.01695 -0.12275"/>
      <geometry>
        <mesh filename="meshes/rg2_gripper/right_outer_link_1.obj" scale="0.001 0.001 0.001"/>
      </geometry>
    </collision>
  </link>
  <link name="right_finger_link_1">
    <inertial>
      <origin rpy="0 0 0" xyz="0.009987219235276384 0.010687647568778226 0.02740261610670347"/>
      <mass value="0.02483517715757534"/>
      <inertia ixx="7e-06" ixy="-0.0" ixz="-0.0" iyy="6e-06" iyz="-2e-06" izz="1e-06"/>
    </inertial>
    <visual>
      <origin rpy="0 0 0" xyz="0.0103 0.01892 -0.177715"/>
      <geometry>
        <mesh filename="meshes/rg2_gripper/right_finger_link_1.obj" scale="0.001 0.001 0.001"/>
      </geometry>
      <material name="dark_default"/>
    </visual>
    <collision>
      <origin rpy="0 0 0" xyz="0.0103 0.01892 -0.177715"/>
      <geometry>
        <mesh filename="meshes/rg2_gripper/right_finger_link_1.obj" scale="0.001 0.001 0.001"/>
      </geometry>
    </collision>
  </link>
  <link name="right_inner_link_1">
    <inertial>
      <origin rpy="0 0 0" xyz="0.00999470341305246 0.001693726839305438 -0.035162328885795485"/>
      <mass value="0.012641568013611078"/>
      <inertia ixx="5e-06" ixy="0.0" ixz="0.0" iyy="6e-06" iyz="0.0" izz="1e-06"/>
    </inertial>
    <visual>
      <origin rpy="0 0 0" xyz="0.0103 0.00942 -0.194215"/>
      <geometry>
        <mesh filename="meshes/rg2_gripper/right_inner_link_1.obj" scale="0.001 0.001 0.001"/>
      </geometry>
      <material name="green_default"/>
    </visual>
    <collision>
      <origin rpy="0 0 0" xyz="0.0103 0.00942 -0.194215"/>
      <geometry>
        <mesh filename="meshes/rg2_gripper/right_inner_link_1.obj" scale="0.001 0.001 0.001"/>
      </geometry>
    </collision>
  </link>
  <!-- joints - main serial chain -->
  <joint name="base_link-base_link_inertia" type="fixed">
    <parent link="base_link"/>
    <child link="base_link_inertia"/>
    <!-- 'base_link' is REP-103 aligned (so X+ forward), while the internal
           frames of the robot/controller have X+ pointing backwards.
           Use the joint between 'base_link' and 'base_link_inertia' (a dummy
           link/frame) to introduce the necessary rotation over Z (of pi rad).
      -->
    <origin rpy="0 0 3.141592653589793" xyz="0 0 0"/>
  </joint>
  <joint name="shoulder_pan_joint" type="revolute">
    <parent link="base_link_inertia"/>
    <child link="shoulder_link"/>
    <origin rpy="0 0 0" xyz="0 0 0.089159"/>
    <axis xyz="0 0 1"/>
    <limit effort="150.0" lower="-6.283185307179586" upper="6.283185307179586" velocity="3.141592653589793"/>
    <dynamics damping="0" friction="0"/>
  </joint>
  <joint name="shoulder_lift_joint" type="revolute">
    <parent link="shoulder_link"/>
    <child link="upper_arm_link"/>
    <origin rpy="1.570796327 0 0" xyz="0 0 0"/>
    <axis xyz="0 0 1"/>
    <limit effort="150.0" lower="-6.283185307179586" upper="6.283185307179586" velocity="3.141592653589793"/>
    <dynamics damping="0" friction="0"/>
  </joint>
  <joint name="elbow_joint" type="revolute">
    <parent link="upper_arm_link"/>
    <child link="forearm_link"/>
    <origin rpy="0 0 0" xyz="-0.425 0 0"/>
    <axis xyz="0 0 1"/>
    <limit effort="150.0" lower="-3.141592653589793" upper="3.141592653589793" velocity="3.141592653589793"/>
    <dynamics damping="0" friction="0"/>
  </joint>
  <joint name="wrist_1_joint" type="revolute">
    <parent link="forearm_link"/>
    <child link="wrist_1_link"/>
    <origin rpy="0 0 0" xyz="-0.39225 0 0.10915"/>
    <axis xyz="0 0 1"/>
    <limit effort="28.0" lower="-6.283185307179586" upper="6.283185307179586" velocity="3.141592653589793"/>
    <dynamics damping="0" friction="0"/>
  </joint>
  <joint name="wrist_2_joint" type="revolute">
    <parent link="wrist_1_link"/>
    <child link="wrist_2_link"/>
    <origin rpy="1.570796327 0 0" xyz="0 -0.09465 -1.941303950897609e-11"/>
    <axis xyz="0 0 1"/>
    <limit effort="28.0" lower="-6.283185307179586" upper="6.283185307179586" velocity="3.141592653589793"/>
    <dynamics damping="0" friction="0"/>
  </joint>
  <joint name="wrist_3_joint" type="revolute">
    <parent link="wrist_2_link"/>
    <child link="wrist_3_link"/>
    <origin rpy="1.570796326589793 3.141592653589793 3.141592653589793" xyz="0 0.0823 -1.688001216681175e-11"/>
    <axis xyz="0 0 1"/>
    <limit effort="28.0" lower="-6.283185307179586" upper="6.283185307179586" velocity="3.141592653589793"/>
    <dynamics damping="0" friction="0"/>
  </joint>
  <!-- Gripper Joints -->
  <joint name="wrist_3-gr2" type="fixed">
    <parent link="wrist_3_link"/>
    <child link="base_link_rg2"/>
    <axis xyz="0 0 1"/>
    <origin rpy="0 0 +1.5707963267948966" xyz="0 0 0"/>
    <limit effor="28.0" lower="-6.283185307179586" upper="6.283185307179586" velocity="3.141592653589793"/>
    <dynamics damping="0" friction="0"/>
  </joint>
  <joint name="Rev33" type="revolute">
    <origin rpy="0 0 0" xyz="-0.0103 0.01705 0.12275"/>
    <parent link="base_link_rg2"/>
    <child link="left_outer_link_1"/>
    <axis xyz="-1.0 0.0 0.0"/>
    <limit effort="100" lower="0.0" upper="1.343904" velocity="100"/>
  </joint>
  <joint name="Rev29" type="revolute">
    <origin rpy="0 0 0" xyz="0.0 0.00197 0.054965"/>
    <parent link="left_outer_link_1"/>
    <child link="left_finger_link_1"/>
    <axis xyz="1.0 -0.0 -0.0"/>
    <limit effort="200" lower="0.0" upper="1.343904" velocity="100"/>
  </joint>
  <joint name="Rev30" type="revolute">
    <origin rpy="0 0 0" xyz="0.0 -0.0095 0.0165"/>
    <parent link="left_finger_link_1"/>
    <child link="left_inner_link_1"/>
    <axis xyz="-1.0 -0.0 -0.0"/>
    <limit effort="200" lower="0.0" upper="1.343904" velocity="100"/>
  </joint>
  <joint name="Rev28" type="revolute">
    <origin rpy="0 0 0" xyz="-0.0103 -0.01695 0.12275"/>
    <parent link="base_link_rg2"/>
    <child link="right_outer_link_1"/>
    <axis xyz="1.0 0.0 0.0"/>
    <limit effort="100" lower="0.0" upper="1.343904" velocity="100"/>
  </joint>
  <joint name="Rev34" type="revolute">
    <origin rpy="0 0 0" xyz="0.0 -0.00197 0.054965"/>
    <parent link="right_outer_link_1"/>
    <child link="right_finger_link_1"/>
    <axis xyz="-1.0 -0.0 -0.0"/>
    <limit effort="200" lower="0.0" upper="1.343904" velocity="100"/>
  </joint>
  <joint name="Rev35" type="revolute">
    <origin rpy="0 0 0" xyz="0.0 0.0095 0.0165"/>
    <parent link="right_finger_link_1"/>
    <child link="right_inner_link_1"/>
    <axis xyz="1.0 0.0 -0.0"/>
    <limit effort="200" lower="0.0" upper="1.343904" velocity="100"/>
  </joint>
</robot>
